Workbook

Sheet Quiz
A1: Αρ. Ταυτότητας | B1: Quiz 1 | C1: Quiz 2 | D1: Quiz 3 | E1: Quiz 4 | F1: Quiz 5 | G1: Quiz 6 | H1: Quiz 7 | I1: Quiz 8 | J1: Quiz 9 | K1: Quiz 10 | L1: Quiz 11 | M1: Quiz 12 | N1: Quiz 13 | O1: Quiz 14 | P1: Quiz 15 | Q1: Quiz 16 | R1: Quiz 17 | S1: Quiz 18 | T1: Quiz 19 | U1: Quiz 20 | V1: Quiz Total
A2: 230 | C2: 4 | D2: 16 | E2: 4 | F2: 4 | G2: 12 | H2: 12 | I2: 4 | J2: 12 | K2: 20 | L2: 12 | V2: =$V$42 * ( (SUM(B2:U2))/((SUM($B$46:$U$46))*$B$42) ) -> 1
A3: 434 | C3: 12 | D3: 12 | E3: 4 | F3: 4 | G3: 4 | H3: 8 | K3: 4 | L3: 4 | V3: =$V$42 * ( (SUM(B3:U3))/((SUM($B$46:$U$46))*$B$42) ) -> 0.52
A4: 556 | C4: 12 | D4: 16 | E4: 4 | F4: 4 | G4: 15 | H4: 12 | I4: 4 | J4: 12 | K4: 20 | L4: 12 | V4: =$V$42 * ( (SUM(B4:U4))/((SUM($B$46:$U$46))*$B$42) ) -> 1.11
A5: 731 | C5: 4 | D5: 4 | E5: 4 | F5: 4 | H5: 4 | I5: 4 | J5: 12 | K5: 20 | L5: 4 | V5: =$V$42 * ( (SUM(B5:U5))/((SUM($B$46:$U$46))*$B$42) ) -> 0.6
A6: 1032 | C6: 16 | D6: 12 | E6: 12 | F6: 12 | G6: 4 | H6: 4 | I6: 4 | J6: 4 | K6: 12 | L6: 12 | V6: =$V$42 * ( (SUM(B6:U6))/((SUM($B$46:$U$46))*$B$42) ) -> 0.92
A7: 1199 | C7: 18 | D7: 18 | E7: 4 | F7: 12 | G7: 20 | H7: 20 | I7: 4 | J7: 12 | K7: 4 | L7: 20 | V7: =$V$42 * ( (SUM(B7:U7))/((SUM($B$46:$U$46))*$B$42) ) -> 1.32
A8: 1653 | C8: 16 | D8: 14 | E8: 4 | F8: 4 | G8: 4 | H8: 4 | I8: 4 | K8: 20 | L8: 20 | V8: =$V$42 * ( (SUM(B8:U8))/((SUM($B$46:$U$46))*$B$42) ) -> 0.9
A9: 1786 | D9: 12 | E9: 20 | G9: 4 | H9: 12 | I9: 4 | J9: 4 | K9: 20 | L9: 20 | V9: =$V$42 * ( (SUM(B9:U9))/((SUM($B$46:$U$46))*$B$42) ) -> 0.96
A10: 2040 | C10: 16 | D10: 12 | E10: 20 | F10: 12 | I10: 4 | J10: 4 | L10: 4 | V10: =$V$42 * ( (SUM(B10:U10))/((SUM($B$46:$U$46))*$B$42) ) -> 0.72
A11: 2283 | C11: 4 | D11: 4 | E11: 4 | F11: 4 | H11: 20 | I11: 12 | J11: 4 | K11: 20 | L11: 20 | V11: =$V$42 * ( (SUM(B11:U11))/((SUM($B$46:$U$46))*$B$42) ) -> 0.92
A12: 2293 | C12: 12 | D12: 12 | E12: 4 | F12: 12 | G12: 12 | H12: 4 | I12: 12 | J12: 4 | K12: 4 | L12: 20 | V12: =$V$42 * ( (SUM(B12:U12))/((SUM($B$46:$U$46))*$B$42) ) -> 0.96
A13: 2376 | C13: 12 | D13: 14 | E13: 4 | F13: 4 | G13: 4 | H13: 12 | I13: 12 | J13: 4 | K13: 4 | L13: 20 | V13: =$V$42 * ( (SUM(B13:U13))/((SUM($B$46:$U$46))*$B$42) ) -> 0.9
A14: 2438 | C14: 16 | D14: 18 | E14: 4 | F14: 4 | G14: 12 | H14: 12 | I14: 12 | J14: 12 | K14: 4 | L14: 20 | V14: =$V$42 * ( (SUM(B14:U14))/((SUM($B$46:$U$46))*$B$42) ) -> 1.14
A15: 2476 | C15: 18 | D15: 20 | E15: 20 | F15: 20 | G15: 12 | H15: 20 | I15: 20 | J15: 4 | K15: 20 | L15: 20 | V15: =$V$42 * ( (SUM(B15:U15))/((SUM($B$46:$U$46))*$B$42) ) -> 1.74
A16: 2979 | C16: 4 | D16: 12 | E16: 14 | F16: 4 | G16: 4 | H16: 20 | I16: 4 | J16: 4 | K16: 20 | L16: 20 | V16: =$V$42 * ( (SUM(B16:U16))/((SUM($B$46:$U$46))*$B$42) ) -> 1.06
A17: 3132 | V17: =$V$42 * ( (SUM(B17:U17))/((SUM($B$46:$U$46))*$B$42) ) -> 0
A18: 3183 | C18: 14 | D18: 18 | E18: 4 | F18: 4 | G18: 4 | J18: 12 | K18: 20 | L18: 12 | V18: =$V$42 * ( (SUM(B18:U18))/((SUM($B$46:$U$46))*$B$42) ) -> 0.88
A19: 3190 | C19: 4 | D19: 14 | E19: 16 | F19: 12 | G19: 12 | H19: 4 | I19: 4 | J19: 12 | K19: 20 | L19: 4 | V19: =$V$42 * ( (SUM(B19:U19))/((SUM($B$46:$U$46))*$B$42) ) -> 1.02
A20: 3192 | D20: 20 | E20: 12 | F20: 4 | G20: 4 | H20: 16 | I20: 12 | J20: 4 | K20: 20 | L20: 20 | V20: =$V$42 * ( (SUM(B20:U20))/((SUM($B$46:$U$46))*$B$42) ) -> 1.12
A21: 3217 | C21: 16 | D21: 12 | E21: 16 | F21: 4 | G21: 20 | H21: 20 | I21: 12 | J21: 4 | L21: 20 | V21: =$V$42 * ( (SUM(B21:U21))/((SUM($B$46:$U$46))*$B$42) ) -> 1.24
A22: 3279 | C22: 12 | D22: 14 | E22: 4 | F22: 12 | G22: 12 | I22: 12 | J22: 4 | K22: 4 | L22: 12 | V22: =$V$42 * ( (SUM(B22:U22))/((SUM($B$46:$U$46))*$B$42) ) -> 0.86
A23: 3360 | C23: 18 | D23: 16 | E23: 20 | F23: 4 | G23: 20 | H23: 20 | I23: 16 | J23: 4 | K23: 20 | L23: 20 | V23: =$V$42 * ( (SUM(B23:U23))/((SUM($B$46:$U$46))*$B$42) ) -> 1.58
A24: 3466 | D24: 12 | E24: 12 | F24: 4 | G24: 4 | H24: 16 | I24: 12 | J24: 12 | K24: 20 | L24: 20 | V24: =$V$42 * ( (SUM(B24:U24))/((SUM($B$46:$U$46))*$B$42) ) -> 1.12
A25: 3474 | C25: 18 | D25: 20 | E25: 8 | H25: 20 | I25: 12 | J25: 4 | K25: 20 | L25: 20 | V25: =$V$42 * ( (SUM(B25:U25))/((SUM($B$46:$U$46))*$B$42) ) -> 1.22
A26: 3481 | C26: 12 | D26: 4 | E26: 4 | F26: 4 | G26: 4 | H26: 8 | I26: 4 | J26: 4 | K26: 4 | L26: 4 | V26: =$V$42 * ( (SUM(B26:U26))/((SUM($B$46:$U$46))*$B$42) ) -> 0.52
A27: 4218 | C27: 12 | E27: 4 | F27: 12 | G27: 4 | I27: 12 | J27: 4 | K27: 20 | L27: 12 | V27: =$V$42 * ( (SUM(B27:U27))/((SUM($B$46:$U$46))*$B$42) ) -> 0.8
A28: 4365 | C28: 12 | D28: 12 | E28: 4 | F28: 12 | G28: 4 | I28: 12 | J28: 4 | K28: 20 | L28: 12 | V28: =$V$42 * ( (SUM(B28:U28))/((SUM($B$46:$U$46))*$B$42) ) -> 0.92
A29: 4367 | C29: 16 | D29: 14 | E29: 4 | F29: 4 | G29: 4 | H29: 12 | I29: 4 | J29: 12 | K29: 20 | L29: 4 | V29: =$V$42 * ( (SUM(B29:U29))/((SUM($B$46:$U$46))*$B$42) ) -> 0.94
A30: 4434 | C30: 12 | D30: 12 | E30: 4 | F30: 4 | G30: 12 | H30: 12 | I30: 12 | J30: 4 | K30: 12 | L30: 20 | V30: =$V$42 * ( (SUM(B30:U30))/((SUM($B$46:$U$46))*$B$42) ) -> 1.04
A31: 4449 | C31: 4 | D31: 14 | E31: 4 | F31: 4 | H31: 4 | I31: 4 | K31: 20 | L31: 4 | V31: =$V$42 * ( (SUM(B31:U31))/((SUM($B$46:$U$46))*$B$42) ) -> 0.58
A32: 5282 | C32: 12 | D32: 12 | E32: 12 | F32: 4 | G32: 12 | H32: 4 | I32: 15 | J32: 4 | K32: 4 | L32: 20 | V32: =$V$42 * ( (SUM(B32:U32))/((SUM($B$46:$U$46))*$B$42) ) -> 0.99
A33: 6679 | V33: =$V$42 * ( (SUM(B33:U33))/((SUM($B$46:$U$46))*$B$42) ) -> 0
A34: 7596 | F34: 4 | G34: 12 | H34: 4 | I34: 4 | J34: 12 | K34: 4 | L34: 4 | V34: =$V$42 * ( (SUM(B34:U34))/((SUM($B$46:$U$46))*$B$42) ) -> 0.44
A35: 7618 | C35: 4 | D35: 14 | E35: 1 | F35: 4 | G35: 12 | H35: 16 | I35: 12 | J35: 12 | K35: 4 | L35: 20 | V35: =$V$42 * ( (SUM(B35:U35))/((SUM($B$46:$U$46))*$B$42) ) -> 0.99
A36: 7630 | C36: 12 | G36: 12 | H36: 12 | I36: 4 | J36: 12 | L36: 4 | V36: =$V$42 * ( (SUM(B36:U36))/((SUM($B$46:$U$46))*$B$42) ) -> 0.56
A37: 7651 | C37: 4 | D37: 14 | E37: 20 | F37: 4 | G37: 12 | H37: 16 | I37: 12 | J37: 12 | K37: 4 | L37: 20 | V37: =$V$42 * ( (SUM(B37:U37))/((SUM($B$46:$U$46))*$B$42) ) -> 1.18
A38: 7776 | C38: 12 | D38: 12 | F38: 4 | G38: 12 | J38: 12 | K38: 4 | V38: =$V$42 * ( (SUM(B38:U38))/((SUM($B$46:$U$46))*$B$42) ) -> 0.56
A39: 9852 | C39: 20 | D39: 16 | E39: 20 | F39: 4 | G39: 4 | H39: 12 | I39: 4 | J39: 4 | L39: 20 | V39: =$V$42 * ( (SUM(B39:U39))/((SUM($B$46:$U$46))*$B$42) ) -> 1.04
A40: 9951 | C40: 16 | D40: 20 | E40: 20 | F40: 12 | H40: 4 | I40: 4 | J40: 4 | L40: 4 | V40: =$V$42 * ( (SUM(B40:U40))/((SUM($B$46:$U$46))*$B$42) ) -> 0.84
...

Sheet Exams
A1: Αρ. Ταυτότητας | B1: Πρόοδος | C1: Τελική Εξέταση
A2: 230
A3: 434
A4: 556
A5: 731
A6: 1032
A7: 1199
A8: 1653
A9: 1786
A10: 2040
A11: 2283
A12: 2293
A13: 2376
... A40: 9951
A42: Max Score | B42: 100 | C42: 100
A43: Average | B43: =AVERAGE(B$2:B$40) -> #DIV/0! | C43: =AVERAGE(C$2:C$40) -> #DIV/0!
A44: Std. Dev. | B44: =STDEV(B$2:B$40) -> #DIV/0! | C44: =STDEV(C$2:C$40) -> #DIV/0!
A45: Median | B45: =MEDIAN(B$2:B$40) -> #NUM! | C45: =MEDIAN(C$2:C$40) -> #NUM!

Sheet Grades
A1: Αρ. Ταυτότητας | B1: Quiz Total | C1: Πρόοδος | D1: Τελική Εξέταση | E1: Τελικός Βαθμός | F1: Βαθμός | G1: Passed
A2: 230 | B2: =Quiz!V2 -> 1 | C2: =Exams!B2 -> 0 | D2: =Exams!C2 -> 0 | E2: =$B2+($C2/$C$42)*3.5+($D2/$D$42)*4.5 -> 1 | F2: =0.5*INT(E2/0.5)+INT( ((E2-INT(E2/0.5)*0.5)/0.25))*0.5 -> 1 | G2: =IF(F2>4.75,1,0) -> 0
A3: 434 | B3: =Quiz!V3 -> 0.52 | C3: =Exams!B3 -> 0 | D3: =Exams!C3 -> 0 | E3: =$B3+($C3/$C$42)*3.5+($D3/$D$42)*4.5 -> 0.52 | F3: =0.5*INT(E3/0.5)+INT( ((E3-INT(E3/0.5)*0.5)/0.25))*0.5 -> 0.5 | G3: =IF(F3>4.75,1,0) -> 0
A4: 556 | B4: =Quiz!V4 -> 1.11 | C4: =Exams!B4 -> 0 | D4: =Exams!C4 -> 0 | E4: =$B4+($C4/$C$42)*3.5+($D4/$D$42)*4.5 -> 1.11 | F4: =0.5*INT(E4/0.5)+INT( ((E4-INT(E4/0.5)*0.5)/0.25))*0.5 -> 1 | G4: =IF(F4>4.75,1,0) -> 0
A5: 731 | B5: =Quiz!V5 -> 0.6 | C5: =Exams!B5 -> 0 | D5: =Exams!C5 -> 0 | E5: =$B5+($C5/$C$42)*3.5+($D5/$D$42)*4.5 -> 0.6 | F5: =0.5*INT(E5/0.5)+INT( ((E5-INT(E5/0.5)*0.5)/0.25))*0.5 -> 0.5 | G5: =IF(F5>4.75,1,0) -> 0
A6: 1032 | B6: =Quiz!V6 -> 0.92 | C6: =Exams!B6 -> 0 | D6: =Exams!C6 -> 0 | E6: =$B6+($C6/$C$42)*3.5+($D6/$D$42)*4.5 -> 0.92 | F6: =0.5*INT(E6/0.5)+INT( ((E6-INT(E6/0.5)*0.5)/0.25))*0.5 -> 1 | G6: =IF(F6>4.75,1,0) -> 0
A7: 1199 | B7: =Quiz!V7 -> 1.32 | C7: =Exams!B7 -> 0 | D7: =Exams!C7 -> 0 | E7: =$B7+($C7/$C$42)*3.5+($D7/$D$42)*4.5 -> 1.32 | F7: =0.5*INT(E7/0.5)+INT( ((E7-INT(E7/0.5)*0.5)/0.25))*0.5 -> 1.5 | G7: =IF(F7>4.75,1,0) -> 0
A8: 1653 | B8: =Quiz!V8 -> 0.9 | C8: =Exams!B8 -> 0 | D8: =Exams!C8 -> 0 | E8: =$B8+($C8/$C$42)*3.5+($D8/$D$42)*4.5 -> 0.9 | F8: =0.5*INT(E8/0.5)+INT( ((E8-INT(E8/0.5)*0.5)/0.25))*0.5 -> 1 | G8: =IF(F8>4.75,1,0) -> 0
A9: 1786 | B9: =Quiz!V9 -> 0.96 | C9: =Exams!B9 -> 0 | D9: =Exams!C9 -> 0 | E9: =$B9+($C9/$C$42)*3.5+($D9/$D$42)*4.5 -> 0.96 | F9: =0.5*INT(E9/0.5)+INT( ((E9-INT(E9/0.5)*0.5)/0.25))*0.5 -> 1 | G9: =IF(F9>4.75,1,0) -> 0
A10: 2040 | B10: =Quiz!V10 -> 0.72 | C10: =Exams!B10 -> 0 | D10: =Exams!C10 -> 0 | E10: =$B10+($C10/$C$42)*3.5+($D10/$D$42)*4.5 -> 0.72 | F10: =0.5*INT(E10/0.5)+INT( ((E10-INT(E10/0.5)*0.5)/0.25))*0.5 -> 0.5 | G10: =IF(F10>4.75,1,0) -> 0
A11: 2283 | B11: =Quiz!V11 -> 0.92 | C11: =Exams!B11 -> 0 | D11: =Exams!C11 -> 0 | E11: =$B11+($C11/$C$42)*3.5+($D11/$D$42)*4.5 -> 0.92 | F11: =0.5*INT(E11/0.5)+INT( ((E11-INT(E11/0.5)*0.5)/0.25))*0.5 -> 1 | G11: =IF(F11>4.75,1,0) -> 0
A12: 2293 | B12: =Quiz!V12 -> 0.96 | C12: =Exams!B12 -> 0 | D12: =Exams!C12 -> 0 | E12: =$B12+($C12/$C$42)*3.5+($D12/$D$42)*4.5 -> 0.96 | F12: =0.5*INT(E12/0.5)+INT( ((E12-INT(E12/0.5)*0.5)/0.25))*0.5 -> 1 | G12: =IF(F12>4.75,1,0) -> 0
A13: 2376 | B13: =Quiz!V13 -> 0.9 | C13: =Exams!B13 -> 0 | D13: =Exams!C13 -> 0 | E13: =$B13+($C13/$C$42)*3.5+($D13/$D$42)*4.5 -> 0.9 | F13: =0.5*INT(E13/0.5)+INT( ((E13-INT(E13/0.5)*0.5)/0.25))*0.5 -> 1 | G13: =IF(F13>4.75,1,0) -> 0
... A40: 9951 | B40: =Quiz!V40 -> 0.84 | C40: =Exams!B40 -> 0 | D40: =Exams!C40 -> 0 | E40: =$B40+($C40/$C$42)*3.5+($D40/$D$42)*4.5 -> 0.84 | F40: =0.5*INT(E40/0.5)+INT( ((E40-INT(E40/0.5)*0.5)/0.25))*0.5 -> 1 | G40: =IF(F40>4.75,1,0) -> 0
A42: Max Score | B42: =Quiz!V42 -> 2 | C42: =Exams!B42 -> 100 | D42: =Exams!C42 -> 100 | E42: 10 | F42: 10 | G42: =SUM(G2:G40) -> 0
A43: Average | B43: =AVERAGE(B$2:B$40) -> 0.90282051 | C43: =AVERAGE(C$2:C$40) -> 0 | D43: =AVERAGE(D$2:D$40) -> 0 | E43: =AVERAGE(E$2:E$40) -> 0.90282051 | F43: =AVERAGE(F$2:F$40) -> 0.88461538 | G43: =AVERAGE(G$2:G$40) -> 0
A44: Std. Dev. | B44: =STDEV(B$2:B$40) -> 0.34589281 | C44: =STDEV(C$2:C$40) -> 0 | D44: =STDEV(D$2:D$40) -> 0 | E44: =STDEV(E$2:E$40) -> 0.34589281 | F44: =STDEV(F$2:F$40) -> 0.33367054 | G44: =STDEV(G$2:G$40) -> 0
A45: Median | B45: =MEDIAN(B$2:B$40) -> 0.94 | C45: =MEDIAN(C$2:C$40) -> 0 | D45: =MEDIAN(D$2:D$40) -> 0 | E45: =MEDIAN(E$2:E$40) -> 0.94 | F45: =MEDIAN(F$2:F$40) -> 1 | G45: =MEDIAN(G$2:G$40) -> 0
